Workbook

Sheet Instructions
H2: IMU GOALS
B4: Lucky Star
B5: Program Name | H5: Red | I5: 0 | J5: =I6-1E-23 -> -0.04
B6: PRODUCT DESCRIPTION | C6: <Insert Product Description from PCN> | E6: SAMPLE DATE | F6: <Enter sample submit date> | H6: Yellow | I6: =J6-0.04 -> -0.04 | J6: =I7-1E-21 -> -1e-21
H7: Green | I7: =SUMIF(Dropdowns!$G$3:$G$19,Instructions!B5,Dropdowns!H3:H19) -> 0 | J7: 1
B8: PRODUCT/SAMPLE DETAILS
B9: MFG STYLE # | C9: <List the MFG Style number entered in PCN> | D9: PCN ITEM ID | F9: <List the PCN Item ID from PCN>>
B10: APEX ID | C10: <List the APEX ID number from PCN> | D10: SPARK PID | F10: <List the Product ID from SPARK>
B11: FIRST COST | C11: <List the item first cost entered in PCN> | D11: COUNTRY OF EXPORT | F11: <List the country where Target takes possion of the item>
B12: PCN RETAIL | C12: <List the item unit retail from PCN> | D12: DUTY RATE | F12: <List the duty rate for the item that was entered in PCN>
B13: IMU (AUTO-CALC) | C13: =IFERROR((C12-C11)/C12,"FIELD WILL AUTO CALCULATE BASED ON COST AND RETAIL ENTERED") -> FIELD WILL AUTO CALCULATE BASED ON COST AND RETAIL ENTERED
B14: LY IMU (AUTO-CALC) | C14: =IFERROR((C13-C12)/C13,"FIELD WILL AUTO CALCULATE BASED ON COST, RETAIL AND DUTY ENTERED") -> FIELD WILL AUTO CALCULATE BASED ON COST, RETAIL AND DUTY ENTERED
B15: FOR CARRY FORWARD/UPDATED ITEMS ONLY | D15: MFG STYLE NUMBER BARCODE
B16: LAST YEAR DPCI | C16: <Insert LY DPCI of Similar/CF Item if applicable> | D16: <Insert your MFG Style Number Barcode in this space>
B17: LY FIRST COST | C17: <Insert First Cost from LY item if applicable>
B18: LY RETAIL | C18: <Insert Retail from LY item if applicable>
B19: LY DUTY RATE | C19: <Insert Duty Rate from LY item if applicable>
B20: LY IMU (AUTO-CALC) | C20: =IFERROR((C18-C17)/C18,"FIELD WILL AUTO CALC") -> FIELD WILL AUTO CALC
B21: LY IMU w/DUTY (AUTO-CALC) | C21: =IFERROR((C19-C18)/C19,"FIELD WILL AUTO CALC") -> FIELD WILL AUTO CALC
B22: THUMBNAIL IMAGE | C22: COMMENTS | F22: RETAIL
B23: <Insert a thumbnail image of the sample in this space> | C23: <Use this space to include any notes or comments about the item that the Target team should know about. If this is a new version of an existing sample, please note what has changed from the previous sample.> | F23: <The retail entered above will also show here for ease of visibility when working through submissions>

Sheet Template
B2: =Instructions!$B$4 -> Lucky Star | H2: =Instructions!$B$4 -> Lucky Star
B3: =Instructions!$B$5 -> Program Name | H3: =Instructions!$B$5 -> Program Name
B4: PRODUCT DESCRIPTION | E4: SAMPLE DATE | H4: PRODUCT DESCRIPTION | K4: SAMPLE DATE
B6: PRODUCT/SAMPLE DETAILS | H6: PRODUCT/SAMPLE DETAILS
B7: MFG STYLE # | D7: PCN ITEM ID | H7: MFG STYLE # | J7: PCN ITEM ID
B8: APEX ID | D8: SPARK PID | H8: APEX ID | J8: SPARK PID
B9: FIRST COST | D9: COUNTRY OF EXPORT | H9: FIRST COST | J9: COUNTRY OF EXPORT
B10: PCN RETAIL | D10: DUTY RATE | H10: PCN RETAIL | J10: DUTY RATE
B11: IMU (AUTO-CALC) | C11: =IFERROR((C10-C9)/C10,"FIELD WILL AUTO CALC") -> FIELD WILL AUTO CALC | H11: IMU (AUTO-CALC) | I11: =IFERROR((I10-I9)/I10,"FIELD WILL AUTO CALC") -> FIELD WILL AUTO CALC
B12: IMU w/DUTY (AUTO-CALC) | C12: =IFERROR((C10-((F10*C9)+C9))/C10, "FIELD WILL AUTO CALC") -> FIELD WILL AUTO CALC | H12: IMU w/DUTY (AUTO-CALC) | I12: =IFERROR((I10-((L10*I9)+I9))/I10, "FIELD WILL AUTO CALC") -> FIELD WILL AUTO CALC
B13: FOR CARRY FORWARD/UPDATED ITEMS ONLY | D13: MFG STYLE NUMBER BARCODE | H13: FOR CARRY FORWARD/UPDATED ITEMS ONLY | J13: MFG STYLE NUMBER BARCODE
B14: LAST YEAR DPCI | H14: LAST YEAR DPCI
B15: LY FIRST COST | H15: LY FIRST COST
B16: LY RETAIL | H16: LY RETAIL
B17: LY DUTY RATE | H17: LY DUTY RATE
B18: LY IMU (AUTO-CALC) | C18: =IFERROR((C16-C15)/C16,"FIELD WILL AUTO CALC") -> FIELD WILL AUTO CALC | H18: LY IMU (AUTO-CALC) | I18: =IFERROR((I16-I15)/I16,"FIELD WILL AUTO CALC") -> FIELD WILL AUTO CALC
B19: LY IMU w/DUTY (AUTO-CALC) | C19: =IFERROR((C16-((C17*C15)+C15))/C16, "FIELD WILL AUTO CALC") -> FIELD WILL AUTO CALC | H19: LY IMU w/DUTY (AUTO-CALC) | I19: =IFERROR((I16-((I17*I15)+I15))/I16, "FIELD WILL AUTO CALC") -> FIELD WILL AUTO CALC
B20: THUMBNAIL IMAGE | C20: COMMENTS | F20: RETAIL | H20: THUMBNAIL IMAGE | I20: COMMENTS | L20: RETAIL
B21: [INSERT THUMBNAIL IMAGE HERE] | F21: =C10 -> 0 | H21: [INSERT THUMBNAIL IMAGE HERE] | L21: =I10 -> 0
B27: =Instructions!$B$4 -> Lucky Star | H27: =Instructions!$B$4 -> Lucky Star
B28: =Instructions!$B$5 -> Program Name | H28: =Instructions!$B$5 -> Program Name
B29: PRODUCT DESCRIPTION | E29: SAMPLE DATE | H29: PRODUCT DESCRIPTION | K29: SAMPLE DATE
B31: PRODUCT/SAMPLE DETAILS | H31: PRODUCT/SAMPLE DETAILS
B32: MFG STYLE # | D32: PCN ITEM ID | H32: MFG STYLE # | J32: PCN ITEM ID
B33: APEX ID | D33: SPARK PID | H33: APEX ID | J33: SPARK PID
B34: FIRST COST | D34: COUNTRY OF EXPORT | H34: FIRST COST | J34: COUNTRY OF EXPORT
B35: PCN RETAIL | D35: DUTY RATE | H35: PCN RETAIL | J35: DUTY RATE
B36: IMU (AUTO-CALC) | C36: =IFERROR((C35-C34)/C35,"FIELD WILL AUTO CALC") -> FIELD WILL AUTO CALC | H36: IMU (AUTO-CALC) | I36: =IFERROR((I35-I34)/I35,"FIELD WILL AUTO CALC") -> FIELD WILL AUTO CALC
B37: IMU w/DUTY (AUTO-CALC) | C37: =IFERROR((C35-((F35*C34)+C34))/C35, "FIELD WILL AUTO CALC") -> FIELD WILL AUTO CALC | H37: IMU w/DUTY (AUTO-CALC) | I37: =IFERROR((I35-((L35*I34)+I34))/I35, "FIELD WILL AUTO CALC") -> FIELD WILL AUTO CALC
B38: FOR CARRY FORWARD/UPDATED ITEMS ONLY | D38: MFG STYLE NUMBER BARCODE | H38: FOR CARRY FORWARD/UPDATED ITEMS ONLY | J38: MFG STYLE NUMBER BARCODE
B39: LAST YEAR DPCI | H39: LAST YEAR DPCI
B40: LY FIRST COST | H40: LY FIRST COST
B41: LY RETAIL | H41: LY RETAIL
B42: LY DUTY RATE | H42: LY DUTY RATE
B43: LY IMU (AUTO-CALC) | C43: =IFERROR((C41-C40)/C41,"FIELD WILL AUTO CALC") -> FIELD WILL AUTO CALC | H43: LY IMU (AUTO-CALC) | I43: =IFERROR((I41-I40)/I41,"FIELD WILL AUTO CALC") -> FIELD WILL AUTO CALC
B44: LY IMU w/DUTY (AUTO-CALC) | C44: =IFERROR((C41-((C42*C40)+C40))/C41, "FIELD WILL AUTO CALC") -> FIELD WILL AUTO CALC | H44: LY IMU w/DUTY (AUTO-CALC) | I44: =IFERROR((I41-((I42*I40)+I40))/I41, "FIELD WILL AUTO CALC") -> FIELD WILL AUTO CALC
B45: THUMBNAIL IMAGE | C45: COMMENTS | F45: RETAIL | H45: THUMBNAIL IMAGE | I45: COMMENTS | L45: RETAIL
B46: [INSERT THUMBNAIL IMAGE HERE] | F46: =C35 -> 0 | H46: [INSERT THUMBNAIL IMAGE HERE] | L46: =I35 -> 0
B52: =Instructions!$B$4 -> Lucky Star | H52: =Instructions!$B$4 -> Lucky Star
B53: =Instructions!$B$5 -> Program Name | H53: =Instructions!$B$5 -> Program Name
...

Sheet Dropdowns
B2: Sample Details | D2: Vendor Name | E2: Color | G2: Program Name | H2: IMU Goal | I2: IMU+Duty Goal | K2: IMU+DUTY GOALS
B3: YES | D3: Champ Home | E3: Dark Grey | G3: Sugar Paper | H3: 0.7514 | I3: 0.78
B4: NO | D4: Creative Design | E4: Light Blue | G4: Boo Basket & Wrap | H4: 0.8561 | I4: 0.88
D5: Garven | E5: Dark Blue | G5: Fall | H5: 0.8671 | I5: 0.88 | K5: Red | L5: 0 | M5: =L6-1E-23 -> -0.04
D6: Solo Murni | E6: Dark Purple | K6: Yellow | L6: =M6-0.04 -> -0.04 | M6: =L7-1E-21 -> -1e-21
D7: Lucky Star | E7: Magenta | K7: Green | L7: =SUMIF($G$3:$G$22,Instructions!B5,$I$3:$I$22) -> 0 | M7: 1
D8: PTG | E8: Teal
D9: MFR | E9: Dark Red
D10: Novelty Handicraft | E10: Green
E11: Turq
E12: Light Grey
D13: Team Youth | E13: Lilac
D14: Crescent | E14: Light Orange
D15: VNG | E15: Light Pink
D16: Seasons Limited | E16: Yellow
E17: Dark Green
E18: White
E19: Light Green
E20: Orange
E21: Bright Red
E22: Tan
D28: Sourcing!Sourcing!
